Traceback (most recent call last):
  File "C:\Users\seanc\AppData\Roaming\Python\Python38\site-packages\jupyter_cache\executors\utils.py", line 51, in single_nb_execution
    executenb(
  File "C:\Users\seanc\AppData\Roaming\Python\Python38\site-packages\nbclient\client.py", line 1117, in execute
    return NotebookClient(nb=nb, resources=resources, km=km, **kwargs).execute()
  File "C:\Users\seanc\AppData\Roaming\Python\Python38\site-packages\nbclient\util.py", line 78, in wrapped
    return just_run(coro(*args, **kwargs))
  File "C:\Users\seanc\AppData\Roaming\Python\Python38\site-packages\nbclient\util.py", line 57, in just_run
    return loop.run_until_complete(coro)
  File "c:\program files\python38\lib\asyncio\base_events.py", line 616, in run_until_complete
    return future.result()
  File "C:\Users\seanc\AppData\Roaming\Python\Python38\site-packages\nbclient\client.py", line 558, in async_execute
    await self.async_execute_cell(
  File "C:\Users\seanc\AppData\Roaming\Python\Python38\site-packages\nbclient\client.py", line 862, in async_execute_cell
    self._check_raise_for_error(cell, exec_reply)
  File "C:\Users\seanc\AppData\Roaming\Python\Python38\site-packages\nbclient\client.py", line 765, in _check_raise_for_error
    raise CellExecutionError.from_cell_and_msg(cell, exec_reply_content)
nbclient.exceptions.CellExecutionError: An error occurred while executing the following cell:
------------------
#Let's read in our packages
import findspark
findspark.init()
------------------

[1;31m---------------------------------------------------------------------------[0m
[1;31mValueError[0m                                Traceback (most recent call last)
[1;32m~\AppData\Local\Temp/ipykernel_8944/1462247433.py[0m in [0;36m<module>[1;34m[0m
[0;32m      1[0m [1;31m#Let's read in our packages[0m[1;33m[0m[1;33m[0m[1;33m[0m[0m
[0;32m      2[0m [1;32mimport[0m [0mfindspark[0m[1;33m[0m[1;33m[0m[0m
[1;32m----> 3[1;33m [0mfindspark[0m[1;33m.[0m[0minit[0m[1;33m([0m[1;33m)[0m[1;33m[0m[1;33m[0m[0m
[0m
[1;32m~\AppData\Roaming\Python\Python38\site-packages\findspark.py[0m in [0;36minit[1;34m(spark_home, python_path, edit_rc, edit_profile)[0m
[0;32m    127[0m [1;33m[0m[0m
[0;32m    128[0m     [1;32mif[0m [1;32mnot[0m [0mspark_home[0m[1;33m:[0m[1;33m[0m[1;33m[0m[0m
[1;32m--> 129[1;33m         [0mspark_home[0m [1;33m=[0m [0mfind[0m[1;33m([0m[1;33m)[0m[1;33m[0m[1;33m[0m[0m
[0m[0;32m    130[0m [1;33m[0m[0m
[0;32m    131[0m     [1;32mif[0m [1;32mnot[0m [0mpython_path[0m[1;33m:[0m[1;33m[0m[1;33m[0m[0m

[1;32m~\AppData\Roaming\Python\Python38\site-packages\findspark.py[0m in [0;36mfind[1;34m()[0m
[0;32m     33[0m [1;33m[0m[0m
[0;32m     34[0m     [1;32mif[0m [1;32mnot[0m [0mspark_home[0m[1;33m:[0m[1;33m[0m[1;33m[0m[0m
[1;32m---> 35[1;33m         raise ValueError(
[0m[0;32m     36[0m             [1;34m"Couldn't find Spark, make sure SPARK_HOME env is set"[0m[1;33m[0m[1;33m[0m[0m
[0;32m     37[0m             [1;34m" or Spark is in an expected location (e.g. from homebrew installation)."[0m[1;33m[0m[1;33m[0m[0m

[1;31mValueError[0m: Couldn't find Spark, make sure SPARK_HOME env is set or Spark is in an expected location (e.g. from homebrew installation).
ValueError: Couldn't find Spark, make sure SPARK_HOME env is set or Spark is in an expected location (e.g. from homebrew installation).

